Workbook

Sheet Componentes
A1: # | B1: Subsistema | C1: Componente | D1: Modelo / especificación | E1: Cantidad | F1: Para qué | G1: Estado | H1: Dónde conseguir | I1: Precio unitario (ARS) | J1: Total (ARS) | K1: Notas
A2: 1 | B2: Procesamiento | C2: Teensy 4.1 | D2: PJRC Teensy 4.1 (600 MHz), puente VIN–VUSB cortado | E2: 1 | F2: Núcleo: muestreo a 1000 Hz, SD, lógica | G2: Ya lo tengo | H2: Importar | J2: =IF(I2="","",E2*I2) | K2: Puente VIN–VUSB ya cortado.
A3: 2 | B3: Procesamiento | C3: Tarjeta microSD | D3: SanDisk Max Endurance (32–64 GB) | E3: 1 | F3: Guardar las bajadas .sfb | G3: Ya lo tengo | H3: Local | J3: =IF(I3="","",E3*I3)
A4: 3 | B4: Procesamiento | C4: Extensor de microSD | D4: Pinqiongzhe, 10 cm | E4: 1 | F4: Acceso a la SD desde afuera de la caja | G4: Ya lo tengo | H4: Importar | J4: =IF(I4="","",E4*I4) | K4: Punto débil con vibración de DH. Usarlo en banco; en pista, SD en la ranura del Teensy trabada con silicona, y bajar por WiFi (ESP32-C3). Revisar si es necesario o conveniente usar
A5: 4 | B5: Procesamiento | C5: Pila del reloj | D5: CR1220 3 V + portapila | E5: 1 | F5: Que el reloj siga en hora con el Sender apagado (VBAT) | G5: Comprar | H5: Local | J5: =IF(I5="","",E5*I5) | K5: Nuevo 26/09.
A6: 5 | B6: Sensores | C6: Regla horquilla | D6: KTC-200 (200 mm) | E6: 1 | F6: Recorrido de la horquilla, 1000 Hz | G6: Comprar | H6: Importar | J6: =IF(I6="","",E6*I6)
A7: 6 | B7: Sensores | C7: Regla shock | D7: KTC-100 (100 mm) | E7: 1 | F7: Recorrido del shock, 1000 Hz | G7: Comprar | H7: Importar | J7: =IF(I7="","",E7*I7)
A8: 7 | B8: Sensores | C8: Acelerómetro de impacto | D8: ADXL375 (±200 g, SPI) | E8: 1 | F8: Golpes y topes, 1000 Hz | G8: Ya lo tengo | H8: Importar | J8: =IF(I8="","",E8*I8) | K8: Firmware lo configura a 1600 Hz.
A9: 8 | B9: Sensores | C9: Acelerómetro + giroscopio (actual) | D9: MPU-6050 (placa GY-521) | E9: 1 | F9: Aceleración de baja amplitud/baja frecuencia (chatter, caída libre de los saltos) y giros | G9: Sacar del diseño | H9: — | J9: =IF(I9="","",E9*I9) | K9: Lo reemplaza un IMU moderno por SPI (fila siguiente). Por I2C tarda ~400 µs por lectura.
A10: 9 | B10: Sensores | C10: Acelerómetro + giroscopio (nuevo) | D10: ICM-42688-P por SPI (alternativa: LSM6DSO32 Adafruit, ±32 g) | E10: 1 | F10: Mismo rol que el MPU: lo que el ADXL375 no resuelve (49 mg por cuenta): chatter, caída libre de saltos, giros. 1000 Hz | G10: Comprar | H10: Importar | J10: =IF(I10="","",E10*I10) | K10: ±16 g con ~0,5 mg por cuenta, giro hasta ±2000 °/s, filtro anti-aliasing programable. Comparte SPI con el ADXL375 (CS propio, pin 26). Lectura ~20 µs.
A11: 10 | B11: Sensores | C11: IMU de orientación | D11: Adafruit BNO055 | E11: 1 | F11: Tumbada y cabeceo, 100 Hz. Bus I2C lento (24/25) | G11: Ya lo tengo | H11: Importar | J11: =IF(I11="","",E11*I11) | K11: Cambia de bus: pines 24/25.
A12: 11 | B12: Sensores | C12: Barómetro (actual) | D12: Adafruit BMP280 | E12: 1 | F12: Altimetría y temperatura | G12: Sacar del diseño | H12: — | J12: =IF(I12="","",E12*I12) | K12: Lo reemplaza el BMP580.
A13: 12 | B13: Sensores | C13: Barómetro (nuevo) | D13: BMP580 (módulo 3,3 V o con regulador) + filtro de jeringa | E13: 1 | F13: Altimetría (saltos, drops, fusión con GPS), 10–25 Hz. Bus I2C lento (24/25) | G13: Comprar | H13: Local | J13: =IF(I13="","",E13*I13) | K13: Elegido 26/09 porque se consigue en Argentina (el BMP390 había que importarlo). ±0,5 m relativo (el BMP280 ±1 m), ruido ~1 cm. Entrega presión ya compensada. Dirección 0x47 (o 0x46). Máximo 3,6 V.
A14: 13 | B14: Sensores | C14: GPS | D14: SparkFun GNSS L1/L5 NEO-F10N (SMA) | E14: 1 | F14: Posición y velocidad, 10 Hz multi-GNSS | G14: Ya lo tengo | H14: Importar | J14: =IF(I14="","",E14*I14) | K14: Cablear también su salida PPS (pulso por segundo) al pin 23 del Teensy: sincroniza el reloj con la hora GPS.
A15: 14 | B15: Sensores | C15: Antena GPS | D15: Antena activa L1/L5 (doble banda) con SMA | E15: 1 | F15: La placa con SMA no trae antena | G15: Comprar | H15: Importar | J15: =IF(I15="","",E15*I15) | K15: Verificar que sea L1+L5 y el conector correcto.
A16: 15 | B16: Sensores | C16: Sensor de rueda | D16: SMC D-Z73 (reed con LED) + imán | E16: 1 | F16: Velocidad de rueda delantera (eventos) | G16: Ya lo tengo | H16: Local/Importar | J16: =IF(I16="","",E16*I16)
A17: 16 | B17: Sensores | C17: Temperatura del amortiguador | D17: DS18B20 TO-92 (pack x3) | E17: 1 | F17: Temperatura de horquilla y shock, por el cable de la regla. Además IDENTIFICA el sensor (número de serie único) | G17: Comprar | H17: Local | J17: =IF(I17="","",E17*I17) | K17: Pack de 3: 2 en uso + 1 de repuesto. Su número de serie le dice al Sender qué regla está enchufada y en qué conector.
A18: 17 | B18: Sensores | C18: Portasensor de temperatura | D18: Plaquita de aluminio ~15×10×3 mm con cajera para TO-92 | E18: 2 | F18: Montar el DS18B20 bajo la abrazadera de la regla | G18: Fabricar | H18: Taller propio | J18: =IF(I18="","",E18*I18) | K18: Epoxi (mejor térmico) + termocontraíble.
A19: 18 | B19: Sensores | C19: Sensor de freno | D19: Sensor de corte de freno e-bike, tipo reed (2 cables) + imán | E19: 2 | F19: Detectar cada frenada sin tocar el hidráulico (conectores 4 y 5) | G19: Decidir | H19: Local | J19: =IF(I19="","",E19*I19) | K19: Futuro. Va al pin digital de un conector universal.
A20: 19 | B20: Sensores | C20: Temperatura IR | D20: MLX90614 (DCI 5° o BCF 10°) | E20: 2 | F20: Alternativa sin contacto al DS18B20 | G20: Descartado | H20: Importar | J20: =IF(I20="","",E20*I20) | K20: Reemplazado por el DS18B20 (26/09), salvo que se reconsidere.
A21: 20 | B21: Sensores | C21: Presión de cubiertas | D21: TPMS Bluetooth (Presta, o Schrader + adaptador) | E21: 2 | F21: Presión real de cada cubierta | G21: Decidir | H21: A definir | J21: =IF(I21="","",E21*I21) | K21: Elegir modelo y verificar su protocolo antes de comprar.
A22: 21 | B22: Sensores | C22: Altura sobre el suelo | D22: LiDAR TFmini-S / TFmini Plus | E22: 1 | F22: Altura real en saltos | G22: Futuro | H22: Importar | J22: =IF(I22="","",E22*I22) | K22: Opcional, versión posterior.
A23: 22 | B23: Comunicación | C23: WiFi + Bluetooth | D23: ESP32-C3 SuperMini (pack x2) | E23: 1 | F23: Bajar bajadas por WiFi, pulsómetro/TPMS por Bluetooth | G23: Comprar | H23: Local | J23: =IF(I23="","",E23*I23) | K23: Pack de 2. Probar el alcance de la antena apenas llegue.
A24: 23 | B24: Comunicación | C24: WiFi (actual) | D24: ESP8266 ESP-01S | E24: 1 | F24: WiFi mientras no esté el ESP32-C3 | G24: Sacar del diseño | H24: — | J24: =IF(I24="","",E24*I24) | K24: Se reemplaza por el ESP32-C3.
A25: 24 | B25: Comunicación | C25: Bluetooth (actual) | D25: Adafruit Bluefruit LE UART | E25: 1 | F25: Pulsómetro | G25: Sacar del diseño | H25: — | J25: =IF(I25="","",E25*I25) | K25: Lo hace el ESP32-C3. Libera los pines 0/1.
A26: 25 | B26: Alimentación | C26: Batería | D26: LiPo 1S 3000 mAh (103665) | E26: 1 | F26: Alimentación | G26: Ya lo tengo | H26: Local | J26: =IF(I26="","",E26*I26) | K26: Tenés 2: el diseño usa una sola; la otra queda de repuesto.
A27: 26 | B27: Alimentación | C27: Cargador | D27: TP4056 variante HW-373 | E27: 1 | F27: Carga de la batería | G27: Ya lo tengo | H27: Local | J27: =IF(I27="","",E27*I27) | K27: Tenés 2: el diseño usa uno solo; el otro queda de repuesto.
A28: 27 | B28: Alimentación | C28: Step-up 12 V | D28: MT3608 | E28: 1 | F28: 12 V para el sensor de rueda (los botones ya no llevan LED) | G28: Ya lo tengo | H28: Local | J28: =IF(I28="","",E28*I28) | K28: Se alimenta desde la llave del pin 4. Plan B del WiFi: de acá, con un reductor a 5 V.
A29: 28 | B29: Alimentación | C29: MOSFET 12 V (actual) | D29: IRF9530 | E29: 1 | F29: Corte del riel de 12 V | G29: Sacar del diseño | H29: — | J29: =IF(I29="","",E29*I29) | K29: No es de nivel lógico; lo reemplazan las llaves de los pines 4 y 9.
A30: 29 | B30: Alimentación | C30: P-MOSFET nivel lógico | D30: AO3401A / SI2301 (SMD) o NDP6020P (TO-220) | E30: 2 | F30: Llaves de alimentación Q1 (periféricos) y Q3 (WiFi) | G30: Comprar | H30: Local/Importar | J30: =IF(I30="","",E30*I30)
A31: 30 | B31: Alimentación | C31: N-MOSFET | D31: 2N7000 / BS170 (TO-92) o 2N7002 (SMD) | E31: 2 | F31: Manejan el gate de Q1 y Q3 desde los pines 4 y 9 | G31: Comprar | H31: Local | J31: =IF(I31="","",E31*I31)
A32: 31 | B32: Alimentación | C32: Resistencia 100 kΩ | D32: 1/4 W | E32: 4 | F32: Gates de las llaves | G32: Comprar | H32: Local | J32: =IF(I32="","",E32*I32)
A33: 32 | B33: Alimentación | C33: Resistencia 1 kΩ | D33: 1/4 W | E33: 4 | F33: Gates de las llaves | G33: Ya lo tengo | H33: Local | J33: =IF(I33="","",E33*I33)
A34: 33 | B34: Alimentación | C34: Alimentación del ESP32-C3 | D34: Sin regulador extra: batería (después de la llave del pin 9) al pin 5V del SuperMini; su regulador interno da los 3,3 V | E34: 1 | F34: Alimentar el ESP32-C3 desde la batería | G34: Confirmar | H34: — | J34: =IF(I34="","",E34*I34) | K34: El LM2596 directo de la batería NO sirve (necesita ≥5 V de entrada). Verificar si el SuperMini tiene diodo en la entrada de 5 V. Plan B: 12 V del MT3608 → LM2596 o Mini-360 regulado a 5 V → pin 5V (la llave del pin 9 entre medio).
A35: 34 | B35: Alimentación | C35: Capacitor de reserva del WiFi | D35: Electrolítico 470 µF 6,3–10 V (bajo ESR) | E35: 1 | F35: Sostener los picos de ~350 mA del WiFi con batería baja | G35: Comprar | H35: Local | J35: =IF(I35="","",E35*I35) | K35: Pegado a los pines 5V/GND del SuperMini.
A36: 35 | B36: Alimentación | C36: Divisor de batería (actual) | D36: Resistencias 10 kΩ | E36: 2 | F36: Lectura de batería (pin 16) | G36: Sacar del diseño | H36: — | J36: =IF(I36="","",E36*I36) | K36: Lo reemplaza el MAX17048. Libera el pin 16.
A37: 36 | B37: Alimentación | C37: Medidor de batería | D37: MAX17048 (placa Adafruit o similar) | E37: 1 | F37: Porcentaje real de batería (la tensión de una LiPo casi no cambia en la mitad de la descarga) | G37: Comprar | H37: Importar | J37: =IF(I37="","",E37*I37) | K37: Bus I2C lento (24/25), dirección 0x36. Queda siempre conectado a la batería: consume unos µA con el Sender apagado.
A38: 37 | B38: Interfaz | C38: Botón Power | D38: Pulsador metálico ~12 mm MOMENTÁNEO, IP67, SIN LED | E38: 1 | F38: Prender (pin On/Off) y apagar | G38: Comprar | H38: Local | J38: =IF(I38="","",E38*I38) | K38: Cambio 26/09: más chico y sin anillo LED; el estado lo muestra la tira de LEDs. No más chico que ~12 mm: se usa con guantes.
A39: 38 | B39: Interfaz | C39: Diodo Schottky | D39: BAT43 / 1N5817 | E39: 1 | F39: Que el firmware lea el botón Power (pin 22): apagado prolijo con 2 s | G39: Decidir | H39: Local | J39: =IF(I39="","",E39*I39) | K39: Depende de la decisión abierta 1.
A40: 39 | B40: Interfaz | C40: Botón RUN | D40: Pulsador metálico ~12 mm MOMENTÁNEO, IP67, SIN LED (igual al Power) | E40: 1 | F40: Grabar/parar, WiFi, reinicio | G40: Comprar | H40: Local | J40: =IF(I40="","",E40*I40) | K40: Sin LED ni resistencia de 220 Ω: libera el pin 5. Idealmente de otra forma o color que el Power para distinguirlos al tacto.
...

Sheet Resumen
A1: Estado | B1: Cantidad de ítems | C1: Costo cargado (ARS) | D1: Ítems sin precio
A2: Confirmar | B2: =COUNTIF(Componentes!$G$2:$G$74,A2) | C2: =SUMIFS(Componentes!$J$2:$J$74,Componentes!$G$2:$G$74,A2) | D2: =COUNTIFS(Componentes!$G$2:$G$74,A2,Componentes!$I$2:$I$74,"")
A3: Ya lo tengo | B3: =COUNTIF(Componentes!$G$2:$G$74,A3) | C3: =SUMIFS(Componentes!$J$2:$J$74,Componentes!$G$2:$G$74,A3) | D3: =COUNTIFS(Componentes!$G$2:$G$74,A3,Componentes!$I$2:$I$74,"")
A4: Comprar | B4: =COUNTIF(Componentes!$G$2:$G$74,A4) | C4: =SUMIFS(Componentes!$J$2:$J$74,Componentes!$G$2:$G$74,A4) | D4: =COUNTIFS(Componentes!$G$2:$G$74,A4,Componentes!$I$2:$I$74,"")
A5: Comprado | B5: =COUNTIF(Componentes!$G$2:$G$74,A5) | C5: =SUMIFS(Componentes!$J$2:$J$74,Componentes!$G$2:$G$74,A5) | D5: =COUNTIFS(Componentes!$G$2:$G$74,A5,Componentes!$I$2:$I$74,"")
A6: Fabricar | B6: =COUNTIF(Componentes!$G$2:$G$74,A6) | C6: =SUMIFS(Componentes!$J$2:$J$74,Componentes!$G$2:$G$74,A6) | D6: =COUNTIFS(Componentes!$G$2:$G$74,A6,Componentes!$I$2:$I$74,"")
A7: Decidir | B7: =COUNTIF(Componentes!$G$2:$G$74,A7) | C7: =SUMIFS(Componentes!$J$2:$J$74,Componentes!$G$2:$G$74,A7) | D7: =COUNTIFS(Componentes!$G$2:$G$74,A7,Componentes!$I$2:$I$74,"")
A8: Futuro | B8: =COUNTIF(Componentes!$G$2:$G$74,A8) | C8: =SUMIFS(Componentes!$J$2:$J$74,Componentes!$G$2:$G$74,A8) | D8: =COUNTIFS(Componentes!$G$2:$G$74,A8,Componentes!$I$2:$I$74,"")
A9: Sacar del diseño | B9: =COUNTIF(Componentes!$G$2:$G$74,A9) | C9: =SUMIFS(Componentes!$J$2:$J$74,Componentes!$G$2:$G$74,A9) | D9: =COUNTIFS(Componentes!$G$2:$G$74,A9,Componentes!$I$2:$I$74,"")
A10: Descartado | B10: =COUNTIF(Componentes!$G$2:$G$74,A10) | C10: =SUMIFS(Componentes!$J$2:$J$74,Componentes!$G$2:$G$74,A10) | D10: =COUNTIFS(Componentes!$G$2:$G$74,A10,Componentes!$I$2:$I$74,"")
A11: Total | B11: =SUM(B2:B10) | C11: =SUM(C2:C10) | D11: =SUM(D2:D10)
A13: A comprar (Comprar + Decidir), costo cargado | C13: =C4+C7

Sheet Leyenda
A1: Cómo usar esta planilla
A2: Celdas amarillas | B2: Se completan a mano: Estado (lista desplegable) y Precio unitario. El total y el resumen se calculan solos.
A3: Números en azul | B3: Cantidades tomadas del diseño; cambiarlas si hace falta.
A4: Confirmar | B4: Componente del diseño original: marcar si ya lo tenés (Ya lo tengo) o si hay que comprarlo (Comprar).
A5: Comprar | B5: Nuevo por los cambios del 25–26/09, o reemplazo.
A6: Fabricar | B6: Se hace en el taller (portasensor, carcasa) o se manda a fabricar (PCB).
A7: Decidir | B7: Depende de una decisión abierta de docs/PENDIENTES.md.
A8: Futuro | B8: Opcional para una versión posterior.
A9: Sacar del diseño | B9: Se deja de usar con el armado nuevo.
A10: Descartado | B10: Se evaluó y se eligió otra opción.
A11: Fuente | B11: docs/ARMADO_HARDWARE_SENDER.md, docs/PENDIENTES.md (26/09/2026) y docs/HARDWARE.md sección 7, presión de aire (06/10/2026). Cantidades de resistencias y capacitores: las del circuito, sin repuestos.
A12: Ejemplo | B12: Ítem 16 (fila 17): DS18B20 TO-92 (pack x3), Cantidad 1, Estado Comprar; al comprarlo se pasa a Comprado y se carga el precio.
