Workbook

Sheet Resumen
A1: FlowBench — Prototipo 1: resumen de compras
A2: Costos aproximados en USD, sin cotizar. Se actualiza solo al completar las hojas Compras y Materia prima.
A4: Grupo | B4: Ítems | C4: Subtotal mín (USD) | D4: Subtotal máx (USD) | E4: Cotizado (USD) | F4: Comprados / recibidos
A5: Mecánica comprada | B5: =COUNTIF(Compras!$B$2:$B$103,A5) -> 14 | C5: =SUMIFS(Compras!$I$2:$I$103,Compras!$B$2:$B$103,A5) -> 619 | D5: =SUMIFS(Compras!$J$2:$J$103,Compras!$B$2:$B$103,A5) -> 1302 | E5: =SUMIFS(Compras!$M$2:$M$103,Compras!$B$2:$B$103,A5) -> 0 | F5: =COUNTIFS(Compras!$B$2:$B$103,A5,Compras!$N$2:$N$103,"Comprado")+COUNTIFS(Compras!$B$2:$B$103,A5,Compras!$N$2:$N$103,"Recibido") -> 0
A6: Accionamiento y potencia | B6: =COUNTIF(Compras!$B$2:$B$103,A6) -> 18 | C6: =SUMIFS(Compras!$I$2:$I$103,Compras!$B$2:$B$103,A6) -> 810 | D6: =SUMIFS(Compras!$J$2:$J$103,Compras!$B$2:$B$103,A6) -> 1690 | E6: =SUMIFS(Compras!$M$2:$M$103,Compras!$B$2:$B$103,A6) -> 0 | F6: =COUNTIFS(Compras!$B$2:$B$103,A6,Compras!$N$2:$N$103,"Comprado")+COUNTIFS(Compras!$B$2:$B$103,A6,Compras!$N$2:$N$103,"Recibido") -> 0
A7: Sensores | B7: =COUNTIF(Compras!$B$2:$B$103,A7) -> 9 | C7: =SUMIFS(Compras!$I$2:$I$103,Compras!$B$2:$B$103,A7) -> 643 | D7: =SUMIFS(Compras!$J$2:$J$103,Compras!$B$2:$B$103,A7) -> 1538 | E7: =SUMIFS(Compras!$M$2:$M$103,Compras!$B$2:$B$103,A7) -> 0 | F7: =COUNTIFS(Compras!$B$2:$B$103,A7,Compras!$N$2:$N$103,"Comprado")+COUNTIFS(Compras!$B$2:$B$103,A7,Compras!$N$2:$N$103,"Recibido") -> 0
A8: Electrónica de control | B8: =COUNTIF(Compras!$B$2:$B$103,A8) -> 27 | C8: =SUMIFS(Compras!$I$2:$I$103,Compras!$B$2:$B$103,A8) -> 531.4 | D8: =SUMIFS(Compras!$J$2:$J$103,Compras!$B$2:$B$103,A8) -> 1150 | E8: =SUMIFS(Compras!$M$2:$M$103,Compras!$B$2:$B$103,A8) -> 0 | F8: =COUNTIFS(Compras!$B$2:$B$103,A8,Compras!$N$2:$N$103,"Comprado")+COUNTIFS(Compras!$B$2:$B$103,A8,Compras!$N$2:$N$103,"Recibido") -> 0
A9: Gabinete y seguridad | B9: =COUNTIF(Compras!$B$2:$B$103,A9) -> 13 | C9: =SUMIFS(Compras!$I$2:$I$103,Compras!$B$2:$B$103,A9) -> 515 | D9: =SUMIFS(Compras!$J$2:$J$103,Compras!$B$2:$B$103,A9) -> 1110 | E9: =SUMIFS(Compras!$M$2:$M$103,Compras!$B$2:$B$103,A9) -> 0 | F9: =COUNTIFS(Compras!$B$2:$B$103,A9,Compras!$N$2:$N$103,"Comprado")+COUNTIFS(Compras!$B$2:$B$103,A9,Compras!$N$2:$N$103,"Recibido") -> 0
A10: Montajes y pruebas | B10: =COUNTIF(Compras!$B$2:$B$103,A10) -> 3 | C10: =SUMIFS(Compras!$I$2:$I$103,Compras!$B$2:$B$103,A10) -> 40 | D10: =SUMIFS(Compras!$J$2:$J$103,Compras!$B$2:$B$103,A10) -> 80 | E10: =SUMIFS(Compras!$M$2:$M$103,Compras!$B$2:$B$103,A10) -> 0 | F10: =COUNTIFS(Compras!$B$2:$B$103,A10,Compras!$N$2:$N$103,"Comprado")+COUNTIFS(Compras!$B$2:$B$103,A10,Compras!$N$2:$N$103,"Recibido") -> 0
A11: Servicios tercerizados | B11: =COUNTIF(Compras!$B$2:$B$103,A11) -> 10 | C11: =SUMIFS(Compras!$I$2:$I$103,Compras!$B$2:$B$103,A11) -> 190 | D11: =SUMIFS(Compras!$J$2:$J$103,Compras!$B$2:$B$103,A11) -> 730 | E11: =SUMIFS(Compras!$M$2:$M$103,Compras!$B$2:$B$103,A11) -> 0 | F11: =COUNTIFS(Compras!$B$2:$B$103,A11,Compras!$N$2:$N$103,"Comprado")+COUNTIFS(Compras!$B$2:$B$103,A11,Compras!$N$2:$N$103,"Recibido") -> 0
A12: Herramientas | B12: =COUNTIF(Compras!$B$2:$B$103,A12) -> 8 | C12: =SUMIFS(Compras!$I$2:$I$103,Compras!$B$2:$B$103,A12) -> 210 | D12: =SUMIFS(Compras!$J$2:$J$103,Compras!$B$2:$B$103,A12) -> 1010 | E12: =SUMIFS(Compras!$M$2:$M$103,Compras!$B$2:$B$103,A12) -> 0 | F12: =COUNTIFS(Compras!$B$2:$B$103,A12,Compras!$N$2:$N$103,"Comprado")+COUNTIFS(Compras!$B$2:$B$103,A12,Compras!$N$2:$N$103,"Recibido") -> 0
A13: Materia prima | B13: =COUNTA('Materia prima'!$A$2:$A$24) -> 23 | C13: ='Materia prima'!H25 -> 640 | D13: ='Materia prima'!I25 -> 1340 | E13: ='Materia prima'!K25 -> 0 | F13: =COUNTIF('Materia prima'!$L$2:$L$24,"Comprado")+COUNTIF('Materia prima'!$L$2:$L$24,"Recibido") -> 0
A14: TOTAL con herramientas | B14: =SUM(B5:B13) -> 125 | C14: =SUM(C5:C13) -> 4198.4 | D14: =SUM(D5:D13) -> 9950 | E14: =SUM(E5:E13) -> 0 | F14: =SUM(F5:F13) -> 0
A15: TOTAL sin herramientas | C15: =C14-C12 -> 3988.4 | D15: =D14-D12 -> 8940 | E15: =E14-E12 -> 0
A17: Estado de los ítems de compra
A18: A cotizar | B18: =COUNTIF(Compras!$N$2:$N$103,A18) -> 102
A19: Cotizado | B19: =COUNTIF(Compras!$N$2:$N$103,A19) -> 0
A20: Comprado | B20: =COUNTIF(Compras!$N$2:$N$103,A20) -> 0
A21: Recibido | B21: =COUNTIF(Compras!$N$2:$N$103,A21) -> 0
A22: Descartado | B22: =COUNTIF(Compras!$N$2:$N$103,A22) -> 0
A24: Supuestos:
A25: • Los costos son rangos aproximados de referencia, no cotizaciones. Reemplazalos por el precio real en la columna "Precio unit. cotizado".
A26: • El mecanizado, fresado y rectificado lo hacés vos: solo se presupuesta la materia prima y los tratamientos que conviene tercerizar.
A27: • Columnas, guías del yugo y vástago: barras cromadas de tu stock (costo 0). Verificar las guías en la hoja Guías.
A28: • Mecanismo: scotch yoke con doble rodillo precargado dentro de la base; carrera máxima 200 mm.
A29: • La electrónica es preliminar: se confirma al diseñar la placa de control.
A30: • No incluye mano de obra propia ni horas de diseño.

Sheet Compras
A1: ID | B1: Grupo | C1: Componente | D1: Especificación | E1: Cant. | F1: Unidad | G1: Costo unit. mín (USD) | H1: Costo unit. máx (USD) | I1: Subtotal mín (USD) | J1: Subtotal máx (USD) | K1: Proveedor | L1: Precio unit. cotizado (USD) | M1: Subtotal cotizado (USD) | N1: Estado | O1: Etapa de compra | P1: Notas
A2: M01 | B2: Mecánica comprada | C2: Seguidores de leva (rodillos del yugo) | D2: Ø 35–40 mm con rodamiento, capacidad ≥ 15 kN, perno Ø 20 | E2: 2 | F2: u | G2: 25 | H2: 60 | I2: =E2*G2 -> 50 | J2: =E2*H2 -> 120 | M2: =IF(L2="","",E2*L2) | N2: A cotizar | O2: 2 | P2: Uno de los dos va sobre buje excéntrico (se fabrica) para precargar contra la ranura. Verificar capacidad en catálogo
A3: M02 | B3: Mecánica comprada | C3: Soportes del cigüeñal | D3: Soporte de pie con rodamiento de rodillos a rótula, eje Ø40 | E3: 2 | F3: u | G3: 60 | H3: 125 | I3: =E3*G3 -> 120 | J3: =E3*H3 -> 250 | M3: =IF(L3="","",E3*L3) | N3: A cotizar | O3: 3
A4: M03 | B4: Mecánica comprada | C4: Sellos del vástago | D4: Buje guía (se fabrica en bronce) + rascador + sello para vástago Ø30 | E4: 1 | F4: juego | G4: 15 | H4: 40 | I4: =E4*G4 -> 15 | J4: =E4*H4 -> 40 | M4: =IF(L4="","",E4*L4) | N4: A cotizar | O4: 3 | P4: De tu stock de repuestos de cilindros si tenés la medida
A5: M04 | B5: Mecánica comprada | C5: Rodamientos de repuesto | D5: Un juego de rodillos y rodamientos del cigüeñal | E5: 1 | F5: lote | G5: 20 | H5: 50 | I5: =E5*G5 -> 20 | J5: =E5*H5 -> 50 | M5: =IF(L5="","",E5*L5) | N5: A cotizar | O5: 3
A6: M05 | B6: Mecánica comprada | C6: Limitador de torque | D6: De fricción, para eje Ø40, regulable ≈ 150–200 N·m | E6: 1 | F6: u | G6: 200 | H6: 350 | I6: =E6*G6 -> 200 | J6: =E6*H6 -> 350 | M6: =IF(L6="","",E6*L6) | N6: A cotizar | O6: 3
A7: M06 | B7: Mecánica comprada | C7: Resortes de disco (Belleville) | D7: DIN 2093, pila con precarga ≈ 8 kN para el cartucho de sobrecarga | E7: 1 | F7: juego | G7: 30 | H7: 80 | I7: =E7*G7 -> 30 | J7: =E7*H7 -> 80 | M7: =IF(L7="","",E7*L7) | N7: A cotizar | O7: 3 | P7: Diámetro según diseño del cartucho
A8: M07 | B8: Mecánica comprada | C8: Palancas de traba del puente | D8: Palanca de leva o excéntrica para traba partida, rosca M12–M16 | E8: 2 | F8: u | G8: 10 | H8: 25 | I8: =E8*G8 -> 20 | J8: =E8*H8 -> 50 | M8: =IF(L8="","",E8*L8) | N8: A cotizar | O8: 3 | P8: Como las de LABA7: se traban sin herramientas
A9: M08 | B9: Mecánica comprada | C9: Topes de seguridad | D9: Collar partido Ø 40 con manija, uno por columna | E9: 2 | F9: u | G9: 10 | H9: 25 | I9: =E9*G9 -> 20 | J9: =E9*H9 -> 50 | M9: =IF(L9="","",E9*L9) | N9: A cotizar | O9: 3 | P9: Evitan que el puente caiga al soltar las palancas
A10: M09 | B10: Mecánica comprada | C10: Perillas para pernos de las U | D10: Perilla roscada de ajuste rápido | E10: 4 | F10: u | G10: 3 | H10: 8 | I10: =E10*G10 -> 12 | J10: =E10*H10 -> 32 | M10: =IF(L10="","",E10*L10) | N10: A cotizar | O10: 4
A11: M10 | B11: Mecánica comprada | C11: Fuelle del vástago | D11: Protege el vástago y el rascador del aceite | E11: 1 | F11: u | G11: 10 | H11: 25 | I11: =E11*G11 -> 10 | J11: =E11*H11 -> 25 | M11: =IF(L11="","",E11*L11) | N11: A cotizar | O11: 3
A12: M11 | B12: Mecánica comprada | C12: Patas niveladoras | D12: ≥ 100 kg c/u, base de goma dura | E12: 4 | F12: u | G12: 8 | H12: 15 | I12: =E12*G12 -> 32 | J12: =E12*H12 -> 60 | M12: =IF(L12="","",E12*L12) | N12: A cotizar | O12: 4
A13: M12 | B13: Mecánica comprada | C13: Tornillería de alta resistencia | D13: Clase 10.9 / 12.9; tuercas de columnas | E13: 1 | F13: lote | G13: 60 | H13: 120 | I13: =E13*G13 -> 60 | J13: =E13*H13 -> 120 | M13: =IF(L13="","",E13*L13) | N13: A cotizar | O13: 3
A14: M13 | B14: Mecánica comprada | C14: Chavetas, arandelas, seegers, prisioneros | D14: Surtido | E14: 1 | F14: lote | G14: 20 | H14: 50 | I14: =E14*G14 -> 20 | J14: =E14*H14 -> 50 | M14: =IF(L14="","",E14*L14) | N14: A cotizar | O14: 3
A15: M14 | B15: Mecánica comprada | C15: Lubricantes | D15: Grasa para rodamientos y rodillos, aceite para guías | E15: 1 | F15: lote | G15: 10 | H15: 25 | I15: =E15*G15 -> 10 | J15: =E15*H15 -> 25 | M15: =IF(L15="","",E15*L15) | N15: A cotizar | O15: 5
A16: A01 | B16: Accionamiento y potencia | C16: Motor trifásico | D16: Opción A: 2,2 kW, 4 polos, 1.450 rpm, forma B3 (patas), triángulo 3 × 220 V | E16: 1 | F16: u | G16: 180 | H16: 320 | I16: =E16*G16 -> 180 | J16: =E16*H16 -> 320 | M16: =IF(L16="","",E16*L16) | N16: A cotizar | O16: 2 | P16: Ej. WEG. Confirmar que admite ≈ 3.000 rpm (≈ 100 Hz). Si se elige servomotor (fila A18), descartar esta fila
A17: A02 | B17: Accionamiento y potencia | C17: Variador de frecuencia | D17: Opción A: vectorial sin sensor, entrada 1 × 220 V, salida 3 × 220 V, 2,2 kW, hasta ≈ 100 Hz, entrada STO, Modbus RS-485 | E17: 1 | F17: u | G17: 150 | H17: 350 | I17: =E17*G17 -> 150 | J17: =E17*H17 -> 350 | M17: =IF(L17="","",E17*L17) | N17: A cotizar | O17: 1 | P17: 4 kW con entrada monofásica no se consigue. Verificar si alguno de tus variadores de 2,2 kW cumple
A18: A03 | B18: Accionamiento y potencia | C18: Resistencia de frenado | D18: Según manual del variador | E18: 1 | F18: u | G18: 40 | H18: 100 | I18: =E18*G18 -> 40 | J18: =E18*H18 -> 100 | M18: =IF(L18="","",E18*L18) | N18: A cotizar | O18: 2
A19: A04 | B19: Accionamiento y potencia | C19: Filtro EMC de línea | D19: Monofásico, corriente según variador | E19: 1 | F19: u | G19: 30 | H19: 80 | I19: =E19*G19 -> 30 | J19: =E19*H19 -> 80 | M19: =IF(L19="","",E19*L19) | N19: A cotizar | O19: 4 | P19: Solo si el variador no lo trae incorporado
A20: A05 | B20: Accionamiento y potencia | C20: Polea motriz | D20: HTD 8M, 30 mm de ancho, ≈ 22 dientes | E20: 1 | F20: u | G20: 30 | H20: 60 | I20: =E20*G20 -> 30 | J20: =E20*H20 -> 60 | M20: =IF(L20="","",E20*L20) | N20: A cotizar | O20: 3 | P20: Agujero a medida en tu torno
A21: A06 | B21: Accionamiento y potencia | C21: Polea conducida | D21: HTD 8M, 30 mm de ancho, ≈ 110 dientes (relación 5:1 para la opción A) | E21: 1 | F21: u | G21: 70 | H21: 140 | I21: =E21*G21 -> 70 | J21: =E21*H21 -> 140 | M21: =IF(L21="","",E21*L21) | N21: A cotizar | O21: 3 | P21: Con servomotor, relación 4:1 (≈ 88 dientes)
A22: A07 | B22: Accionamiento y potencia | C22: Correa dentada | D22: HTD 8M-30, largo según CAD | E22: 2 | F22: u | G22: 15 | H22: 30 | I22: =E22*G22 -> 30 | J22: =E22*H22 -> 60 | M22: =IF(L22="","",E22*L22) | N22: A cotizar | O22: 3 | P22: Incluye una de repuesto
A23: A08 | B23: Accionamiento y potencia | C23: Bujes cónicos para poleas | D23: Taper lock según poleas | E23: 2 | F23: u | G23: 10 | H23: 25 | I23: =E23*G23 -> 20 | J23: =E23*H23 -> 50 | M23: =IF(L23="","",E23*L23) | N23: A cotizar | O23: 3 | P23: Opcional si hacés el agujero directo
A24: A09 | B24: Accionamiento y potencia | C24: Interruptor termomagnético | D24: Bipolar, según corriente de entrada del variador (≈ 20–25 A con 2,2 kW) | E24: 1 | F24: u | G24: 20 | H24: 40 | I24: =E24*G24 -> 20 | J24: =E24*H24 -> 40 | M24: =IF(L24="","",E24*L24) | N24: A cotizar | O24: 4 | P24: Dimensiona el electricista
A25: A10 | B25: Accionamiento y potencia | C25: Disyuntor diferencial | D25: Bipolar, tipo apto para variadores | E25: 1 | F25: u | G25: 40 | H25: 80 | I25: =E25*G25 -> 40 | J25: =E25*H25 -> 80 | M25: =IF(L25="","",E25*L25) | N25: A cotizar | O25: 4
A26: A11 | B26: Accionamiento y potencia | C26: Contactor principal | D26: 25 A, bobina 24 VDC, comandado por el relé de seguridad | E26: 1 | F26: u | G26: 25 | H26: 60 | I26: =E26*G26 -> 25 | J26: =E26*H26 -> 60 | M26: =IF(L26="","",E26*L26) | N26: A cotizar | O26: 4
A27: A12 | B27: Accionamiento y potencia | C27: Toma y ficha industrial | D27: 2P+T, 32 A | E27: 1 | F27: juego | G27: 30 | H27: 60 | I27: =E27*G27 -> 30 | J27: =E27*H27 -> 60 | M27: =IF(L27="","",E27*L27) | N27: A cotizar | O27: 4
A28: A13 | B28: Accionamiento y potencia | C28: Cable de alimentación | D28: Sección según corriente | E28: 1 | F28: lote | G28: 20 | H28: 40 | I28: =E28*G28 -> 20 | J28: =E28*H28 -> 40 | M28: =IF(L28="","",E28*L28) | N28: A cotizar | O28: 4
A29: A14 | B29: Accionamiento y potencia | C29: Cable de motor blindado | D29: 4 × 2,5 mm², ≈ 5 m | E29: 1 | F29: lote | G29: 20 | H29: 40 | I29: =E29*G29 -> 20 | J29: =E29*H29 -> 40 | M29: =IF(L29="","",E29*L29) | N29: A cotizar | O29: 4 | P29: Blindado para reducir ruido eléctrico en los sensores
A30: A15 | B30: Accionamiento y potencia | C30: Gabinete eléctrico | D30: Metálico, con ventilación y riel DIN | E30: 1 | F30: u | G30: 60 | H30: 120 | I30: =E30*G30 -> 60 | J30: =E30*H30 -> 120 | M30: =IF(L30="","",E30*L30) | N30: A cotizar | O30: 4
A31: A16 | B31: Accionamiento y potencia | C31: Riel DIN, canal de cables, borneras, terminales | D31: Surtido para el tablero | E31: 1 | F31: lote | G31: 30 | H31: 60 | I31: =E31*G31 -> 30 | J31: =E31*H31 -> 60 | M31: =IF(L31="","",E31*L31) | N31: A cotizar | O31: 4
A32: A17 | B32: Accionamiento y potencia | C32: Fusibles y portafusibles DIN | D32: Para circuitos de 24 V, 12 V y 5 V | E32: 1 | F32: lote | G32: 15 | H32: 30 | I32: =E32*G32 -> 15 | J32: =E32*H32 -> 30 | M32: =IF(L32="","",E32*L32) | N32: A cotizar | O32: 4
A33: A18 | B33: Accionamiento y potencia | C33: Alternativa: servomotor + servodrive | D33: Opción B: servo AC ≈ 3 kW con encoder, drive con entrada 1 × 220 V, torque pico ≈ 3 veces el nominal | E33: 1 | F33: juego | G33: 0 | H33: 0 | I33: =E33*G33 -> 0 | J33: =E33*H33 -> 0 | M33: =IF(L33="","",E33*L33) | N33: A cotizar | O33: 1 | P33: No se suma al total. Cotizar para comparar: confirmar que el drive acepte entrada monofásica a esa potencia
A34: S01 | B34: Sensores | C34: Celda de carga | D34: 10 kN, tracción–compresión, en línea, apta para fatiga, roscas en ambos extremos | E34: 1 | F34: u | G34: 300 | H34: 700 | I34: =E34*G34 -> 300 | J34: =E34*H34 -> 700 | M34: =IF(L34="","",E34*L34) | N34: A cotizar | O34: 2 | P34: Pedir con certificado de calibración. Rosca a definir en CAD
A35: S02 | B35: Sensores | C35: Cable y conector de la celda | D35: Cable blindado + conector M12 | E35: 1 | F35: juego | G35: 15 | H35: 40 | I35: =E35*G35 -> 15 | J35: =E35*H35 -> 40 | M35: =IF(L35="","",E35*L35) | N35: A cotizar | O35: 2
A36: S03 | B36: Sensores | C36: Encoder lineal (cabezal) | D36: Magnético sin contacto, resolución ≤ 1 µm, salida RS-422 incremental o SSI absoluta | E36: 1 | F36: u | G36: 200 | H36: 450 | I36: =E36*G36 -> 200 | J36: =E36*H36 -> 450 | M36: =IF(L36="","",E36*L36) | N36: A cotizar | O36: 2 | P36: Plazo largo: pedir temprano
A37: S04 | B37: Sensores | C37: Cinta magnética del encoder | D37: ≥ 300 mm (recorrido útil ≥ 250 mm) | E37: 1 | F37: u | G37: 50 | H37: 150 | I37: =E37*G37 -> 50 | J37: =E37*H37 -> 150 | M37: =IF(L37="","",E37*L37) | N37: A cotizar | O37: 2
A38: S05 | B38: Sensores | C38: Encoder angular del cigüeñal | D38: Magnético absoluto 14 bits, SPI (ej. AS5048A) | E38: 1 | F38: u | G38: 15 | H38: 40 | I38: =E38*G38 -> 15 | J38: =E38*H38 -> 40 | M38: =IF(L38="","",E38*L38) | N38: A cotizar | O38: 4
A39: S06 | B39: Sensores | C39: Imán diametral para encoder angular | D39: Según encoder | E39: 1 | F39: u | G39: 3 | H39: 8 | I39: =E39*G39 -> 3 | J39: =E39*H39 -> 8 | M39: =IF(L39="","",E39*L39) | N39: A cotizar | O39: 4
A40: S07 | B40: Sensores | C40: Sensores inductivos | D40: M8, PNP, 24 V, para detectar el perno de manivela | E40: 3 | F40: u | G40: 10 | H40: 25 | I40: =E40*G40 -> 30 | J40: =E40*H40 -> 75 | M40: =IF(L40="","",E40*L40) | N40: A cotizar | O40: 4 | P40: El método exacto de identificación del agujero se define en CAD
...

Sheet Materia prima
A1: ID | B1: Pieza / uso | C1: Material | D1: Medida aprox. | E1: Cant. | F1: Costo mín (USD) | G1: Costo máx (USD) | H1: Subtotal mín (USD) | I1: Subtotal máx (USD) | J1: Proveedor | K1: Precio cotizado (USD) | L1: Estado | M1: Notas
A2: MP01 | B2: Columnas | C2: Barra cromada Ø40 de tu stock | D2: Ø40 × ≈ 1.350 mm (≈ 1,2 m libres + anclaje) | E2: 2 | F2: 0 | G2: 0 | H2: =E2*F2 -> 0 | I2: =E2*G2 -> 0 | L2: A cotizar | M2: Solo sostienen el puente: la rectitud y la dureza no son críticas. Largo final según relevamiento
A3: MP02 | B3: Guías del yugo | C3: Barra cromada Ø30 de tu stock | D3: Ø30 × ≈ 450 mm | E3: 2 | F3: 0 | G3: 0 | H3: =E3*F3 -> 0 | I3: =E3*G3 -> 0 | L3: A cotizar | M3: Verificar diámetro y rectitud en la hoja Guías
A4: MP03 | B4: Vástago | C4: Barra cromada Ø30 de tu stock | D4: Ø30 × ≈ 450 mm | E4: 1 | F4: 0 | G4: 0 | H4: =E4*F4 -> 0 | I4: =E4*G4 -> 0 | L4: A cotizar | M4: Como un vástago de cilindro: rosca en las puntas
A5: MP04 | B5: Eje del cigüeñal | C5: SAE 4140 bonificado | D5: Ø45 × 450 mm | E5: 1 | F5: 25 | G5: 50 | H5: =E5*F5 -> 25 | I5: =E5*G5 -> 50 | L5: A cotizar
A6: MP05 | B6: Plato de manivela | C6: SAE 4140 bonificado | D6: Disco Ø270 × 40 mm | E6: 1 | F6: 60 | G6: 120 | H6: =E6*F6 -> 60 | I6: =E6*G6 -> 120 | L6: A cotizar
A7: MP06 | B7: Yugo | C7: SAE 4140 bonificado | D7: Bloque 60 × 90 × 320 mm | E7: 1 | F7: 40 | G7: 80 | H7: =E7*F7 -> 40 | I7: =E7*G7 -> 80 | L7: A cotizar | M7: Ranura fresada; caras templadas (servicio) y rectificadas
A8: MP07 | B8: Pernos (manivela, buje excéntrico) | C8: SAE 4140 o acero para temple | D8: Ø30 × 300 mm | E8: 1 | F8: 10 | G8: 25 | H8: =E8*F8 -> 10 | I8: =E8*G8 -> 25 | L8: A cotizar
A9: MP08 | B9: Bujes de bronce (guías del yugo, puente, vástago) | C9: Bronce SAE 64 | D9: Barra hueca o maciza Ø60 × 400 mm | E9: 1 | F9: 40 | G9: 90 | H9: =E9*F9 -> 40 | I9: =E9*G9 -> 90 | L9: A cotizar | M9: Se terminan ajustados a las barras reales
A10: MP09 | B10: Puente | C10: Acero SAE 1045 o aluminio 7075 | D10: 40 × 100 × 460 mm | E10: 1 | F10: 25 | G10: 70 | H10: =E10*F10 -> 25 | I10: =E10*G10 -> 70 | L10: A cotizar | M10: Con bolsillos para aliviarlo
A11: MP10 | B11: Trabas partidas del puente | C11: SAE 1045 | D11: Planchuela 30 × 80 × 300 mm | E11: 1 | F11: 10 | G11: 25 | H11: =E11*F11 -> 10 | I11: =E11*G11 -> 25 | L11: A cotizar
A12: MP11 | B12: Placa superior de base | C12: Acero F-24 | D12: 25 × 550 × 450 mm | E12: 1 | F12: 60 | G12: 110 | H12: =E12*F12 -> 60 | I12: =E12*G12 -> 110 | L12: A cotizar | M12: Rectificar después de soldar
A13: MP12 | B13: Placa inferior de anclaje de columnas y guías | C13: Acero F-24 | D13: 20 × 500 × 400 mm | E13: 1 | F13: 45 | G13: 90 | H13: =E13*F13 -> 45 | I13: =E13*G13 -> 90 | L13: A cotizar
A14: MP13 | B14: Placa de soportes del cigüeñal | C14: Acero F-24 | D14: 25 × 400 × 300 mm | E14: 1 | F14: 25 | G14: 50 | H14: =E14*F14 -> 25 | I14: =E14*G14 -> 50 | L14: A cotizar
A15: MP14 | B15: Estructura de base | C15: Tubo estructural 80 × 80 × 3,2 | D15: 1 barra de 6 m | E15: 1 | F15: 40 | G15: 80 | H15: =E15*F15 -> 40 | I15: =E15*G15 -> 80 | L15: A cotizar
A16: MP15 | B16: Cerramiento de base | C16: Chapa 2–3 mm | D16: Según despiece | E16: 1 | F16: 50 | G16: 100 | H16: =E16*F16 -> 50 | I16: =E16*G16 -> 100 | L16: A cotizar
A17: MP16 | B17: U universales, manguito del steerer, bloque de eje, trunnion | C17: Aluminio 7075 | D17: Barra 80 × 80 × 500 mm (lote) | E17: 1 | F17: 50 | G17: 110 | H17: =E17*F17 -> 50 | I17: =E17*G17 -> 110 | L17: A cotizar
A18: MP17 | B18: Separadores y pernos de ojo | C18: Acero para temple | D18: Ø30 × 500 mm | E18: 1 | F18: 15 | G18: 30 | H18: =E18*F18 -> 15 | I18: =E18*G18 -> 30 | L18: A cotizar
A19: MP18 | B19: Volante | C19: Acero | D19: Disco Ø250 × 25 mm (≈ 10 kg) | E19: 1 | F19: 25 | G19: 50 | H19: =E19*F19 -> 25 | I19: =E19*G19 -> 50 | L19: A cotizar
A20: MP19 | B20: Cuerpo del cartucho de sobrecarga | C20: SAE 1045 | D20: Ø70 × 120 mm | E20: 1 | F20: 10 | G20: 20 | H20: =E20*F20 -> 10 | I20: =E20*G20 -> 20 | L20: A cotizar
A21: MP20 | B21: Contrapeso, soportes de motor, tensor | C21: Acero | D21: Planchuela y retazos | E21: 1 | F21: 20 | G21: 40 | H21: =E21*F21 -> 20 | I21: =E21*G21 -> 40 | L21: A cotizar
A22: MP21 | B22: Guardas fijas | C22: Chapa perforada 1,5 mm | D22: 1 plancha | E22: 1 | F22: 30 | G22: 60 | H22: =E22*F22 -> 30 | I22: =E22*G22 -> 60 | L22: A cotizar
A23: MP22 | B23: Soporte del encoder y brazo de pantalla | C23: Aluminio | D23: Perfiles y planchuela | E23: 1 | F23: 20 | G23: 40 | H23: =E23*F23 -> 20 | I23: =E23*G23 -> 40 | L23: A cotizar
A24: MP23 | B24: Consumibles de taller | C24: Electrodos, discos, brocas, insertos, escariadores H7 | D24: Lote | E24: 1 | F24: 40 | G24: 100 | H24: =E24*F24 -> 40 | I24: =E24*G24 -> 100 | L24: A cotizar | M24: Escariadores Ø20 H7 y Ø8 H7 si no los tenés
B25: TOTAL | H25: =SUM(H2:H24) -> 640 | I25: =SUM(I2:I24) -> 1340 | K25: =SUM(K2:K24) -> 0

Sheet Mecanizado
A1: Pieza | B1: Materia prima | C1: Máquina necesaria | D1: ¿Con torno y perforadora? | E1: Recomendación | F1: Tolerancias clave | G1: Hecho
A2: Eje del cigüeñal | B2: MP04 | C2: Torno + rectificadora tangencial | D2: Sí | E2: Asientos de rodamientos y limitador a h6 | F2: h6 en asientos
A3: Plato de manivela | B3: MP05 | C3: Torno + fresado + rectificadora plana | D3: Sí | E3: Caras rectificadas; 23 agujeros H7 fresados y escariados | F3: Posición ± 0,02 mm; H7
A4: Yugo | B4: MP06 | C4: Fresado + rectificadora plana | D4: Sí (temple afuera) | E4: Fresar la ranura, templar las caras (servicio), rectificarlas paralelas. Alojamientos de guías y vástago en una sola atada | F4: Caras paralelas < 0,01 mm; alojamientos paralelos 0,02 mm
A5: Perno de manivela y buje excéntrico | B5: MP07 | C5: Torno + rectificadora tangencial | D5: Sí (temple afuera) | E5: El excéntrico permite precargar los dos rodillos contra la ranura | F5: h6; excentricidad ≈ 0,5 mm
A6: Guías del yugo | B6: MP02 | C6: Torno | D6: Sí | E6: Cortar, refrentar, roscar para fijarlas arriba y abajo | F6: Paralelas entre sí 0,02 mm
A7: Vástago | B7: MP03 | C7: Torno | D7: Sí | E7: Rosca y centrado en las puntas, como un vástago de cilindro
A8: Bujes de bronce | B8: MP08 | C8: Torno | D8: Sí | E8: Terminar a la medida real de cada barra | F8: Juego mínimo sin trabar
A9: Puente | B9: MP09 | C9: Fresado + rectificadora plana | D9: Sí | E9: Bolsillos de alivianado; alojamientos de bujes paralelos | F9: Paralelismo 0,02 mm
A10: Trabas partidas y palancas | B10: MP10 | C10: Torno + fresado | D10: Sí
A11: Placa superior e inferior de base | B11: MP11, MP12 | C11: Rectificadora plana + fresado / perforadora + escariador | D11: Sí | E11: Agujerear las dos placas juntas para que columnas y guías queden paralelas | F11: Perpendicularidad de asientos
A12: Estructura de base soldada | B12: MP14, MP15 | C12: Soldadora | D12: Propio o tercerizar (T07) | E12: Soldar antes de rectificar la placa
A13: Cartucho de sobrecarga | B13: MP19 | C13: Torno | D13: Sí
A14: Volante | B14: MP18 | C14: Torno | D14: Sí | E14: Balancear junto con el plato (T05)
A15: Poleas | B15: A05, A06 | C15: Torno | D15: Sí | E15: Se compran hechas; agujero y chavetero a medida
A16: U universales, manguito del steerer, bloque de eje, trunnion | B16: MP16, MP17 | C16: Torno + fresado | D16: Sí | E16: Pernos de ojo a h6 y templados
A17: Contrapeso, soportes de motor, tensor, guardas | B17: MP20, MP21 | C17: Perforadora + sierra + soldadora | D17: Sí
A18: Soporte del encoder y brazo de pantalla | B18: MP22 | C18: Perforadora | D18: Sí | E18: El encoder tiene que quedar paralelo a las guías

Sheet Guías
A1: Criterio | B1: Objetivo | C1: Por qué | D1: Cómo medirlo | E1: Medido barra 1 | F1: Medido barra 2 | G1: ¿Cumple?
A2: Diámetro | B2: Medir el real y ajustar los bujes de bronce a esa medida | C2: Con bujes de bronce el diámetro exacto no importa: el buje se termina a la barra | D2: Micrómetro en 3 puntos a lo largo y en 2 direcciones a 90°
A3: Ovalidad | B3: < 0,01 mm | C3: Ovalidad = juego que cambia al girar | D3: Diferencia entre las dos mediciones a 90° en un mismo punto
A4: Rectitud | B4: < 0,02 mm en ≈ 300 mm | C4: El yugo recorre ≈ 200 mm sobre las guías | D4: Entre puntas en el torno, con reloj comparador
A5: Paralelismo de las dos guías | B5: < 0,02 mm | C5: Si no son paralelas, el yugo se traba | D5: Reloj comparador desde la placa, montadas
A6: Estado del cromo | B6: Sin poros ni rayas | C6: El bronce trabaja sobre el cromo | D6: Inspección visual
A7: Dureza | B7: Solo si usás bujes de bolas: ≥ 58 HRC | C7: Con bronce no es crítica | D7: Lima de prueba o dato del proveedor
A9: Notas:
A10: • Esta hoja aplica a las guías del yugo y al vástago (dentro de la base).
A11: • Las columnas solo sostienen el puente: con que estén derechas a la vista y sin daños en el cromo, alcanza.

Sheet Leyenda
A1: Cómo usar la planilla
A2: Celdas amarillas | B2: Son las que completás: proveedor, precio cotizado, estado, mediciones y avance.
A3: Texto azul | B3: Valores estimados (cantidad y rangos de costo). Se pueden corregir.
A4: Texto negro en columnas de subtotal | B4: Fórmulas: no editar.
A5: Estado | B5: Lista desplegable: A cotizar → Cotizado → Comprado → Recibido (o Descartado).
A6: Etapa de compra | B6: 1 = antes del CAD · 2 = con el CAD avanzado (plazo largo) · 3 = con los planos cerrados · 4 = durante el mecanizado · 5 = al final
A7: Hojas | B7: Resumen · Compras · Materia prima · Mecanizado · Guías · Leyenda
A9: Ejemplo de fila completada (ficticio)
A10: Componente | B10: Motor trifásico
A11: Proveedor | B11: Nombre del proveedor
A12: Precio unit. cotizado (USD) | B12: 420
A13: Estado | B13: Cotizado
A14: Notas | B14: Plazo de entrega 3 semanas; confirma 3.200 rpm
